<?xml version="1.0" encoding="UTF-8"?>
<!-- Generated by org.testng.reporters.JUnitReportReporter -->
<testsuite hostname="HAMILTON-QA11L" failures="3" tests="3" name="Assertions.Hard_Assertion" time="0.013" errors="0" timestamp="2022-05-11T10:45:24 IST" skipped="0">
  <testcase classname="Assertions.Hard_Assertion" name="test1" time="0.011">
    <failure message="expected [50] but found [20]" type="java.lang.AssertionError">
      <![CDATA[java.lang.AssertionError: expected [50] but found [20]
at org.testng.Assert.fail(Assert.java:110)
at org.testng.Assert.failNotEquals(Assert.java:1413)
at org.testng.Assert.assertEqualsImpl(Assert.java:149)
at org.testng.Assert.assertEquals(Assert.java:131)
at org.testng.Assert.assertEquals(Assert.java:1240)
at org.testng.Assert.assertEquals(Assert.java:1274)
at Assertions.Hard_Assertion.test1(Hard_Assertion.java:12)
at java.base/jdk.internal.reflect.NativeMethodAccessorImpl.invoke0(Native Method)
at java.base/jdk.internal.reflect.NativeMethodAccessorImpl.invoke(NativeMethodAccessorImpl.java:77)
at java.base/jdk.internal.reflect.DelegatingMethodAccessorImpl.invoke(DelegatingMethodAccessorImpl.java:43)
at java.base/java.lang.reflect.Method.invoke(Method.java:568)
at org.testng.internal.invokers.MethodInvocationHelper.invokeMethod(MethodInvocationHelper.java:135)
at org.testng.internal.invokers.TestInvoker.invokeMethod(TestInvoker.java:673)
at org.testng.internal.invokers.TestInvoker.invokeTestMethod(TestInvoker.java:220)
at org.testng.internal.invokers.MethodRunner.runInSequence(MethodRunner.java:50)
at org.testng.internal.invokers.TestInvoker$MethodInvocationAgent.invoke(TestInvoker.java:945)
at org.testng.internal.invokers.TestInvoker.invokeTestMethods(TestInvoker.java:193)
at org.testng.internal.invokers.TestMethodWorker.invokeTestMethods(TestMethodWorker.java:146)
at org.testng.internal.invokers.TestMethodWorker.run(TestMethodWorker.java:128)
at java.base/java.util.ArrayList.forEach(ArrayList.java:1511)
at org.testng.TestRunner.privateRun(TestRunner.java:808)
at org.testng.TestRunner.run(TestRunner.java:603)
at org.testng.SuiteRunner.runTest(SuiteRunner.java:429)
at org.testng.SuiteRunner.runSequentially(SuiteRunner.java:423)
at org.testng.SuiteRunner.privateRun(SuiteRunner.java:383)
at org.testng.SuiteRunner.run(SuiteRunner.java:326)
at org.testng.SuiteRunnerWorker.runSuite(SuiteRunnerWorker.java:52)
at org.testng.SuiteRunnerWorker.run(SuiteRunnerWorker.java:95)
at org.testng.TestNG.runSuitesSequentially(TestNG.java:1249)
at org.testng.TestNG.runSuitesLocally(TestNG.java:1169)
at org.testng.TestNG.runSuites(TestNG.java:1092)
at org.testng.TestNG.run(TestNG.java:1060)
at org.testng.remote.AbstractRemoteTestNG.run(AbstractRemoteTestNG.java:115)
at org.testng.remote.RemoteTestNG.initAndRun(RemoteTestNG.java:251)
at org.testng.remote.RemoteTestNG.main(RemoteTestNG.java:77)
]]>
    </failure>
  </testcase> <!-- test1 -->
  <system-out/>
  <testcase classname="Assertions.Hard_Assertion" name="test3" time="0.001">
    <failure message="expected [true] but found [false]" type="java.lang.AssertionError">
      <![CDATA[java.lang.AssertionError: expected [true] but found [false]
at org.testng.Assert.fail(Assert.java:110)
at org.testng.Assert.failNotEquals(Assert.java:1413)
at org.testng.Assert.assertTrue(Assert.java:56)
at org.testng.Assert.assertTrue(Assert.java:66)
at Assertions.Hard_Assertion.test3(Hard_Assertion.java:33)
at java.base/jdk.internal.reflect.NativeMethodAccessorImpl.invoke0(Native Method)
at java.base/jdk.internal.reflect.NativeMethodAccessorImpl.invoke(NativeMethodAccessorImpl.java:77)
at java.base/jdk.internal.reflect.DelegatingMethodAccessorImpl.invoke(DelegatingMethodAccessorImpl.java:43)
at java.base/java.lang.reflect.Method.invoke(Method.java:568)
at org.testng.internal.invokers.MethodInvocationHelper.invokeMethod(MethodInvocationHelper.java:135)
at org.testng.internal.invokers.TestInvoker.invokeMethod(TestInvoker.java:673)
at org.testng.internal.invokers.TestInvoker.invokeTestMethod(TestInvoker.java:220)
at org.testng.internal.invokers.MethodRunner.runInSequence(MethodRunner.java:50)
at org.testng.internal.invokers.TestInvoker$MethodInvocationAgent.invoke(TestInvoker.java:945)
at org.testng.internal.invokers.TestInvoker.invokeTestMethods(TestInvoker.java:193)
at org.testng.internal.invokers.TestMethodWorker.invokeTestMethods(TestMethodWorker.java:146)
at org.testng.internal.invokers.TestMethodWorker.run(TestMethodWorker.java:128)
at java.base/java.util.ArrayList.forEach(ArrayList.java:1511)
at org.testng.TestRunner.privateRun(TestRunner.java:808)
at org.testng.TestRunner.run(TestRunner.java:603)
at org.testng.SuiteRunner.runTest(SuiteRunner.java:429)
at org.testng.SuiteRunner.runSequentially(SuiteRunner.java:423)
at org.testng.SuiteRunner.privateRun(SuiteRunner.java:383)
at org.testng.SuiteRunner.run(SuiteRunner.java:326)
at org.testng.SuiteRunnerWorker.runSuite(SuiteRunnerWorker.java:52)
at org.testng.SuiteRunnerWorker.run(SuiteRunnerWorker.java:95)
at org.testng.TestNG.runSuitesSequentially(TestNG.java:1249)
at org.testng.TestNG.runSuitesLocally(TestNG.java:1169)
at org.testng.TestNG.runSuites(TestNG.java:1092)
at org.testng.TestNG.run(TestNG.java:1060)
at org.testng.remote.AbstractRemoteTestNG.run(AbstractRemoteTestNG.java:115)
at org.testng.remote.RemoteTestNG.initAndRun(RemoteTestNG.java:251)
at org.testng.remote.RemoteTestNG.main(RemoteTestNG.java:77)
]]>
    </failure>
  </testcase> <!-- test3 -->
  <system-out/>
  <testcase classname="Assertions.Hard_Assertion" name="test2" time="0.001">
    <failure message="did not expect [20] but found [20]" type="java.lang.AssertionError">
      <![CDATA[java.lang.AssertionError: did not expect [20] but found [20]
at org.testng.Assert.fail(Assert.java:110)
at org.testng.Assert.failEquals(Assert.java:1417)
at org.testng.Assert.assertNotEqualsImpl(Assert.java:156)
at org.testng.Assert.assertNotEquals(Assert.java:1986)
at org.testng.Assert.assertNotEquals(Assert.java:2008)
at Assertions.Hard_Assertion.test2(Hard_Assertion.java:23)
at java.base/jdk.internal.reflect.NativeMethodAccessorImpl.invoke0(Native Method)
at java.base/jdk.internal.reflect.NativeMethodAccessorImpl.invoke(NativeMethodAccessorImpl.java:77)
at java.base/jdk.internal.reflect.DelegatingMethodAccessorImpl.invoke(DelegatingMethodAccessorImpl.java:43)
at java.base/java.lang.reflect.Method.invoke(Method.java:568)
at org.testng.internal.invokers.MethodInvocationHelper.invokeMethod(MethodInvocationHelper.java:135)
at org.testng.internal.invokers.TestInvoker.invokeMethod(TestInvoker.java:673)
at org.testng.internal.invokers.TestInvoker.invokeTestMethod(TestInvoker.java:220)
at org.testng.internal.invokers.MethodRunner.runInSequence(MethodRunner.java:50)
at org.testng.internal.invokers.TestInvoker$MethodInvocationAgent.invoke(TestInvoker.java:945)
at org.testng.internal.invokers.TestInvoker.invokeTestMethods(TestInvoker.java:193)
at org.testng.internal.invokers.TestMethodWorker.invokeTestMethods(TestMethodWorker.java:146)
at org.testng.internal.invokers.TestMethodWorker.run(TestMethodWorker.java:128)
at java.base/java.util.ArrayList.forEach(ArrayList.java:1511)
at org.testng.TestRunner.privateRun(TestRunner.java:808)
at org.testng.TestRunner.run(TestRunner.java:603)
at org.testng.SuiteRunner.runTest(SuiteRunner.java:429)
at org.testng.SuiteRunner.runSequentially(SuiteRunner.java:423)
at org.testng.SuiteRunner.privateRun(SuiteRunner.java:383)
at org.testng.SuiteRunner.run(SuiteRunner.java:326)
at org.testng.SuiteRunnerWorker.runSuite(SuiteRunnerWorker.java:52)
at org.testng.SuiteRunnerWorker.run(SuiteRunnerWorker.java:95)
at org.testng.TestNG.runSuitesSequentially(TestNG.java:1249)
at org.testng.TestNG.runSuitesLocally(TestNG.java:1169)
at org.testng.TestNG.runSuites(TestNG.java:1092)
at org.testng.TestNG.run(TestNG.java:1060)
at org.testng.remote.AbstractRemoteTestNG.run(AbstractRemoteTestNG.java:115)
at org.testng.remote.RemoteTestNG.initAndRun(RemoteTestNG.java:251)
at org.testng.remote.RemoteTestNG.main(RemoteTestNG.java:77)
]]>
    </failure>
  </testcase> <!-- test2 -->
  <system-out/>
</testsuite> <!-- Assertions.Hard_Assertion -->
